Workbook
Name _ftn1: Fonction!#REF!
Name _ftn2: Fonction!#REF!
Name _ftn3: Fonction!#REF!
Name _ftn4: Fonction!#REF!
Name _ftn5: Fonction!#REF!
Name _ftnref4: Fonction!#REF!
Name _ftnref5: Fonction!#REF!
Name _Toc194351286: Sommaire!$C$34

Sheet Sommaire
B2: INSTITUT CATHOLIQUE DE PARIS
B3: Faculté de Théologie et de Sciences Religieuses
B4: Cycle des Études du Doctorat
B6: EMMANUEL DUMONT
B8: PRÉCHER, DONNER UN RÔLE A DIEU
B9: Le rôle attribué à Dieu dans les homélies télévisées
B11: 2025
B13: Annexe B : classement des verbes du corpus
B15: Sommaire
B17: Onglet "Corpus"
B18: Informations générales sur le corpus dans son ensemble
C19: Figure 1 : Chronologie des principaux prédicateurs
C20: La taille moyenne des homélies, par année
C21: Figure 2 : Qui prêche au Jour du Seigneur
C22: Taille du corpus selon les logiciels utilisés
C23: Nombre de mots par homélie
C24: Figure 3 : Les mots les plus mentionnés
B26: Onglet "Présence"
B27: Données sur la présence des noms divins
C28: Figure 5 : Combien de fois chaque nom divin est-il nommé ?
C29: Figure 4 : Combien de fois Dieu est-il nommé dans une homélie
C30: Figure 6 : Fréquence des différents noms divins dans les homélies.
C31: Fréquence des noms de Dieu selon les temps liturgique
C32: Figure 7 : Les prédicateurs nomment Dieu plus ou moins souvent, plus ou moins tôt.
C33: Figures 8-9 : Fréquence des noms de Dieu selon les prédicateurs
C34: Figure 10 : Chaque nom divin est utilisé différemment selon les corpus
B36: Onglet "Cooccurrences"
B37: Mots à proximité des noms divins
C38: Figures 11-12 : Les mots associés à "Dieu"
C39: Figures 13-14 : Les mots associés à "Jésus"
C40: Figures 15-16 : Les mots associés à "Christ"
C41: Figures 17-18 : Les mots associés à "Seigneur"
C42: Figure 19 : Chaque nom divin est utilisé avec un champ sémantique différent.
C43: Figure 20 : Le champ lexical de "Dieu" varie selon les prédicateurs.
C44: Figure 21 : Le champ lexical de "Jésus" varie selon les prédicateurs.
B46: Onglet "Fonctions"
B47: Fonction grammaticale attribuée aux noms divins
C48: Figure 23 : Est-il normal que Dieu soit le sujet ou l’objet d’une phrase ?
C49: Figure 24 : Dieu est-il plus souvent sujet, objet, ou complément du nom ?
C50: Figure 25 : Chaque nom divin a son profil grammatical.
...

Sheet Corpus
B1: =Sommaire!B26 -> Onglet "Présence"
B2: =Sommaire!B27 -> Données sur la présence des noms divins
B4: =Sommaire!C19 -> Figure 1 : Chronologie des principaux prédicateurs | R4: Nombre de mots par homélie
C5: 1ere diffusion | D5: dernière diffusion | E5: nb. d'homélies
B6: Guinchat | C6: 1969 | D6: 1980 | E6: 26 | F6: =D6-C6 -> 11 | R6: Date | S6: Nb mots
B7: Joulin | C7: 1969 | D7: 1999 | E7: 99 | F7: =D7-C7 -> 30 | R7: 25537 | S7: 1122
B8: Louvel | C8: 1969 | D8: 1978 | E8: 20 | F8: =D8-C8 -> 9 | R8: 25544 | S8: 1143
B9: Bro | C9: 1970 | D9: 1982 | E9: 27 | F9: =D9-C9 -> 12 | R9: 25551 | S9: 1241
B10: Dagonet | C10: 1970 | D10: 1981 | E10: 42 | F10: =D10-C10 -> 11 | R10: 25558 | S10: 1313
B11: David | C11: 1970 | D11: 2000 | E11: 38 | F11: =D11-C11 -> 30 | R11: 25561 | S11: 890
B12: Maillard | C12: 1971 | D12: 2007 | E12: 35 | F12: =D12-C12 -> 36 | R12: 25562 | S12: 1214
B13: Ponsar | C13: 1971 | D13: 1981 | E13: 31 | F13: =D13-C13 -> 10 | R13: 25565 | S13: 1620
B14: Jorens | C14: 1973 | D14: 2006 | E14: 67 | F14: =D14-C14 -> 33 | R14: 25572 | S14: 1067
B15: Talec | C15: 1973 | D15: 1996 | E15: 67 | F15: =D15-C15 -> 23 | R15: 25579 | S15: 1818
B16: Dubost | C16: 1975 | D16: 2008 | E16: 50 | F16: =D16-C16 -> 33 | R16: 25586 | S16: 1203
B17: Quoist | C17: 1975 | D17: 1989 | E17: 34 | F17: =D17-C17 -> 14 | R17: 25593 | S17: 967
B18: Quilici | C18: 1977 | D18: 1988 | E18: 21 | F18: =D18-C18 -> 11 | R18: 25600 | S18: 808
... B40: René-Luc | C40: 2013 | D40: 2019 | E40: 20 | F40: =D40-C40 -> 6 | R40: 25768 | S40: 1206
R41: 25775 | S41: 1746
B42: La taille des homélies | R42: 25782 | S42: 868
A43: outil : Excell
C44: Nombre de mots (moyenne) | R44: 25789 | S44: 914
B45: 1969 | C45: 1237.2857 | R45: 25796 | S45: 903
B46: 1970 | C46: 1319.0784 | R46: 25803 | S46: 1563
B47: 1971 | C47: 1287.6154 | R47: 25810 | S47: 1164
B48: 1972 | C48: 1323.0976 | R48: 25817 | S48: 1438
B49: 1973 | C49: 1265.8846 | R49: 25824 | S49: 1734
B50: 1974 | C50: 1372 | R50: 25831 | S50: 1244
B51: 1975 | C51: 1249.6852 | R51: 25838 | S51: 1248
B52: 1976 | C52: 1281.98 | R52: 25845 | S52: 1145
B53: 1977 | C53: 1335.3636 | R53: 25852 | S53: 1725
B54: 1978 | C54: 1199.4615 | R54: 25859 | S54: 784
B55: 1979 | C55: 1222.8333 | R55: 25866 | S55: 1442
B56: 1980 | C56: 1058.1455 | R56: 25873 | S56: 1106
... B98: 2022 | C98: 759.66 | R98: 26251 | S98: 1704
R99: 26258 | S99: 1194
R100: 26265 | S100: 1342
B101: =Sommaire!C21 -> Figure 2 : Qui prêche au Jour du Seigneur | R101: 26272 | S101: 1181
A102: outil : Excell | R102: 26279 | S102: 1792
B104: Nb de prédicateurs | C104: % Prédicateurs | D104: % Homélies | R104: 26286 | S104: 915
...

Sheet Présence
B1: =Sommaire!B36 -> Onglet "Cooccurrences"
B2: =Sommaire!B37 -> Mots à proximité des noms divins
B4: =Sommaire!C28 -> Figure 5 : Combien de fois chaque nom divin est-il nommé ? | T4: =Sommaire!C29 -> Figure 4 : Combien de fois Dieu est-il nommé dans une homélie
T5: Outil : spaCy (sans les pronoms personnels)
B6: Dieu | C6: Jésus | D6: Christ | E6: Seigneur | F6: Esprit | G6: Père | H6: Fils | I6: Noms divins | J6: Nb de mots
A7: Excell | B7: 25176 | C7: 18115 | D7: 9854 | E7: 3957 | F7: 3463 | G7: 3717 | H7: 1936 | I7: =SUM(B7:H7) -> 66218 | J7: 2664872 | T7: Date | U7: Nom de Dieu / Mots
A8: Nooj | B8: 24487 | C8: 17835 | D8: 9406 | E8: 3842 | F8: 3351 | G8: 3589 | H8: 1893 | I8: =SUM(B8:H8) -> 64403 | J8: 2907723 | T8: 25537 | U8: 0.020499109
A9: SpaCy | B9: 25150 | C9: 18102 | D9: 3943 | E9: 9778 | F9: 1936 | G9: 3267 | H9: 3638 | I9: =SUM(B9:H9) -> 65814 | J9: 2704140 | T9: 25544 | U9: 0.034995626
A10: Trameur | B10: 25399 | C10: 18139 | D10: 9836 | E10: 3989 | F10: 4456 | G10: 4611 | H10: 3294 | I10: =SUM(B10:H10) -> 69724 | J10: 2832433 | T10: 25551 | U10: 0.04109589
A11: Iramuteq | B11: 24674 | C11: 17854 | D11: 9445 | E11: 3880 | F11: 4142 | G11: 4459 | H11: 3203 | I11: =SUM(B11:H11) -> 67657 | J11: 2830196 | T11: 25558 | U11: 0.034272658
B12: =B9/$J9 -> 0.009300554 | C12: =C9/$J9 -> 0.00669418 | D12: =D9/$J9 -> 0.0014581346 | E12: =E9/$J9 -> 0.003615937 | F12: =F9/$J9 -> 0.00071593926 | G12: =G9/$J9 -> 0.0012081475 | H12: =H9/$J9 -> 0.0013453445 | T12: 25561 | U12: 0.026966292
T13: 25562 | U13: 0.015650741
B14: =Sommaire!C30 -> Figure 6 : Fréquence des différents noms divins dans les homélies. | T14: 25565 | U14: 0.034567901
A15: Outil : Excell | T15: 25572 | U15: 0.0093720712
A16: >0 | B16: 2207 | C16: 1810 | D16: 1030 | E16: 324 | F16: 304 | G16: 134 | H16: 248 | T16: 25579 | U16: 0.022552255
B17: Dieu | C17: Jésus | D17: Christ | E17: Seigneur | F17: Père | G17: Fils | H17: Esprit | T17: 25586 | U17: 0.02078138
A18: >10 | B18: 867 | C18: 537 | D18: 180 | E18: 13 | F18: 26 | G18: 5 | H18: 63 | T18: 25593 | U18: 0.021716649
A19: 10>x>3 | B19: =B16-B18 -> 1340 | C19: =C16-C18 -> 1273 | D19: =D16-D18 -> 850 | E19: =E16-E18 -> 311 | F19: =F16-F18 -> 278 | G19: =G16-G18 -> 129 | H19: =H16-H18 -> 185 | T19: 25600 | U19: 0.023514851
A20: 3 | B20: 214 | C20: 241 | D20: 288 | E20: 221 | F20: 179 | G20: 99 | H20: 107 | T20: 25607 | U20: 0.0053789731
A21: 2 | B21: 199 | C21: 294 | D21: 405 | E21: 369 | F21: 330 | G21: 201 | H21: 240 | T21: 25614 | U21: 0.018782383
A22: 1 | B22: 169 | C22: 271 | D22: 499 | E22: 681 | F22: 614 | G22: 503 | H22: 525 | T22: 25621 | U22: 0.017813268
A23: 0 | B23: 112 | C23: 285 | D23: 679 | E23: 1306 | F23: 1474 | G23: 1964 | H23: 1781 | T23: 25628 | U23: 0.03440367
A24: Total | B24: =SUM(B18:B23) -> 2901 | C24: =SUM(C18:C23) -> 2901 | D24: =SUM(D18:D23) -> 2901 | E24: =SUM(E18:E23) -> 2901 | F24: =SUM(F18:F23) -> 2901 | G24: =SUM(G18:G23) -> 2901 | H24: =SUM(H18:H23) -> 2901 | T24: 25635 | U24: 0.014951121
T25: 25642 | U25: 0.012091898
B26: Fréquence des noms de Dieu selon les temps liturgique | T26: 25649 | U26: 0.020656136
A27: Outil : spaCy | T27: 25663 | U27: 0.030742955
T28: 25670 | U28: 0.014946962
B29: Dieu | C29: Jésus | D29: Christ | E29: Seigneur | F29: Esprit | G29: Fils | H29: Père | I29: Total | T29: 25677 | U29: 0.0080645161
A30: AVENT | B30: 0.010282153 | C30: 0.0047339958 | D30: 0.0024101323 | E30: 0.0023454307 | F30: 0.0011484523 | G30: 0.00072789229 | H30: 0.00087347075 | I30: =SUM(B30:H30) -> 0.022521527 | T30: 25684 | U30: 0.0068597561
A31: T. NOËL | B31: 0.011528382 | C31: 0.0049179364 | D31: 0.0028894451 | E31: 0.0013481277 | F31: 0.00082735565 | G31: 0.0011255397 | H31: 0.0014909201 | I31: =SUM(B31:H31) -> 0.024127707 | T31: 25691 | U31: 0.033261027
A32: T. CARÊME | B32: 0.0093308678 | C32: 0.007918283 | D32: 0.0030487697 | E32: 0.00087310517 | F32: 0.00059626694 | G32: 0.00099377824 | H32: 0.001586496 | I32: =SUM(B32:H32) -> 0.024347567 | T32: 25698 | U32: 0.016985138
A33: T. PASCAL | B33: 0.0073201041 | C33: 0.0074317502 | D33: 0.0047328259 | E33: 0.0017693488 | F33: 0.0031843424 | G33: 0.00047328259 | H33: 0.0018130364 | I33: =SUM(B33:H33) -> 0.02672469 | T33: 25705 | U33: 0.031914894
A34: T. ORDINAIRE | B34: 0.0093686993 | C34: 0.0068119269 | D34: 0.0037139815 | E34: 0.0013938533 | F34: 0.00096497539 | G34: 0.00066805989 | H34: 0.0012656975 | I34: =SUM(B34:H34) -> 0.024187194 | T34: 25712 | U34: 0.017196905
A35: J. Noël | B35: 0.013566658 | C35: 0.0040367049 | D35: 0.00222643 | E35: 0.0012796771 | F35: 0.00017686594 | G35: 0.0013941197 | H35: 0.001196446 | I35: =SUM(B35:H35) -> 0.023876901 | T35: 25719 | U35: 0.0072747622
A36: Rameaux | B36: 0.0085925209 | C36: 0.010407842 | D36: 0.0045080479 | E36: 0.001452257 | F36: 0.00081689459 | G36: 0.001785066 | H36: 0.0031163016 | I36: =SUM(B36:H36) -> 0.03067893 | T36: 25726 | U36: 0.031938326
A37: V. pascale | B37: 0.0050800738 | C37: 0.0082921384 | D37: 0.0066974964 | E37: 0.0015490808 | F37: 0.0006606374 | G37: 0.0006150762 | H37: 0.0010023464 | I37: =SUM(B37:H37) -> 0.023896849 | T37: 25733 | U37: 0.019444444
A38: Baptême | B38: 0.012264552 | C38: 0.008214134 | D38: 0.0042203654 | E38: 0.0008780626 | F38: 0.0032856536 | G38: 0.002407591 | H38: 0.0032856536 | I38: =SUM(B38:H38) -> 0.034556012 | T38: 25740 | U38: 0.027715356
A39: Trinité | B39: 0.017438211 | C39: 0.0051392703 | D39: 0.0035504119 | E39: 0.0010200078 | F39: 0.0057669674 | G39: 0.0040996469 | H39: 0.005531581 | I39: =SUM(B39:H39) -> 0.042546097 | T39: 25754 | U39: 0.021413276
A40: S.Sacrement | B40: 0.0067816543 | C40: 0.0058604469 | D40: 0.0058212466 | E40: 0.0013524108 | F40: 0.00084280674 | G40: 0.00033320267 | H40: 0.0013328107 | I40: =SUM(B40:H40) -> 0.022324579 | T40: 25761 | U40: 0.013732834
A41: Assomption | B41: 0.010483334 | C41: 0.0034638589 | D41: 0.0031427064 | E41: 0.0017663386 | F41: 0.0012157915 | G41: 0.0017204597 | H41: 0.0013534283 | I41: =SUM(B41:H41) -> 0.023145918 | T41: 25768 | U41: 0.029850746
...

Sheet Cooccurrences
B1: =Sommaire!B46 -> Onglet "Fonctions"
B2: =Sommaire!B47 -> Fonction grammaticale attribuée aux noms divins
B4: Cooccurents de "Dieu"
A5: Outil : spaCy
B6: Occurrences | C6: Cooccurrences avec Dieu | D6: Indice de surreprésentation
A7: bonté | B7: 237 | C7: 106 | D7: 3.52
A8: miséricorde | B8: 551 | C8: 239 | D8: 3.42
A9: fils | B9: 3180 | C9: 1367 | D9: 3.3848363
A10: don | B10: 1320 | C10: 510 | D10: 3.04
A11: tendresse | B11: 714 | C11: 265 | D11: 2.92
A12: esprit | B12: 3047 | C12: 1024 | D12: 2.6462068
A13: amour | B13: 8140 | C13: 2479 | D13: 2.3979957
A14: aimer | B14: 5833 | C14: 1644 | D14: 2.2192494
A15: croire | B15: 3803 | C15: 922 | D15: 1.9089778
A16: cœur | B16: 5640 | C16: 1301 | D16: 1.8163288
A17: enfant | B17: 4035 | C17: 907 | D17: 1.769946
A18: vouloir | B18: 5556 | C18: 1174 | D18: 1.6638039
... A21: paix | B21: 2419 | C21: 387 | D21: 1.2597123
B23: Occurrences | C23: Cooccurrences avec Dieu | D23: Indice de surreprésentation
A24: règne | B24: 248 | C24: 137 | D24: 4.35
A25: alliance | B25: 460 | C25: 225 | D25: 3.85
A26: verbe | B26: 268 | C26: 127 | D26: 3.7313433
A27: créateur | B27: 346 | C27: 150 | D27: 3.41
A28: manifester | B28: 266 | C28: 110 | D28: 3.26
A29: sauveur | B29: 272 | C29: 111 | D29: 3.21
A30: révéler | B30: 1083 | C30: 431 | D30: 3.13
A31: créer | B31: 580 | C31: 227 | D31: 3.08
A32: royaume | B32: 1445 | C32: 541 | D32: 2.95
A33: projet | B33: 421 | C33: 157 | D33: 2.94
A34: peuple | B34: 2127 | C34: 789 | D34: 2.9208267
A35: création | B35: 434 | C35: 149 | D35: 2.7
... A50: vie | B50: 13040 | C50: 2438 | D50: 1.4721511
B52: Cooccurents de "Jésus"
B54: Occurrences | C54: Cooccurrences avec Jésus | D54: Indice de surreprésentation
A55: prédication | B55: 133 | C55: 43 | D55: 3.2330827
A56: dénoncer | B56: 154 | C56: 49 | D56: 3.1818182
A57: enseignem, | B57: 229 | C57: 72 | D57: 3.1441048
A58: autorité | B58: 267 | C58: 71 | D58: 2.659176
A59: désigner | B59: 205 | C59: 54 | D59: 2.6341463
A60: prononcer | B60: 317 | C60: 81 | D60: 2.555205
...

Sheet Fonction
B1: =Sommaire!B46 -> Onglet "Fonctions"
B2: =Sommaire!B47 -> Fonction grammaticale attribuée aux noms divins
B4: =Sommaire!C48 -> Figure 23 : Est-il normal que Dieu soit le sujet ou l’objet d’une phrase ? | U4: =Sommaire!C49 -> Figure 24 : Dieu est-il plus souvent sujet, objet, ou complément du nom ?
A5: Répartition des homélies selon le nombre de mentions des noms divins, en pourcentage du nombre total de mots. | T5: Répartition des 5 noms divins selon les fonctions grammaticales qui leur sont attribués
A6: Prise en compte des 5 noms divins, sans les pronoms personnels qui les désignent. | T6: Prise en compte des 5 noms divins, sans les pronoms personnels qui les désignent.
A7: outil : spaCy | T7: outil : spaCy
V8: Quantité | Y8: Répartition par fonction
A9: Mentions des 5 noms divins | B9: Sujet | C9: Objet | U9: Date de l'homélie | V9: Sujets | W9: Objet | X9: Compl. du nom | Y9: Sujets | Z9: Objet | AA9: Compl. du nom
A10: <0% | B10: 22 | C10: 78 | U10: 25537 | V10: 7 | W10: 0 | X10: 14 | Y10: 0.33333333 | Z10: 0 | AA10: 0.66666667
A11: 0-2% | B11: 104 | C11: 355 | U11: 25544 | V11: 17 | W11: 12 | X11: 8 | Y11: 0.45945946 | Z11: 0.32432432 | AA11: 0.21621622
A12: 2-4% | B12: 201 | C12: 657 | U12: 25551 | V12: 20 | W12: 17 | X12: 12 | Y12: 0.40816327 | Z12: 0.34693878 | AA12: 0.24489796
A13: 4-6% | B13: 293 | C13: 602 | U13: 25558 | V13: 18 | W13: 6 | X13: 16 | Y13: 0.45 | Z13: 0.15 | AA13: 0.4
A14: 6-8% | B14: 358 | C14: 475 | U14: 25561 | V14: 11 | W14: 3 | X14: 9 | Y14: 0.47826087 | Z14: 0.13043478 | AA14: 0.39130435
A15: 8-10% | B15: 365 | C15: 302 | U15: 25562 | V15: 1 | W15: 4 | X15: 12 | Y15: 0.058823529 | Z15: 0.23529412 | AA15: 0.70588235
A16: 10-12% | B16: 337 | C16: 183 | U16: 25565 | V16: 17 | W16: 13 | X16: 24 | Y16: 0.31481481 | Z16: 0.24074074 | AA16: 0.44444444
A17: 12-14% | B17: 304 | C17: 116 | U17: 25572 | V17: 3 | W17: 3 | X17: 4 | Y17: 0.3 | Z17: 0.3 | AA17: 0.4
A18: 14-16% | B18: 233 | C18: 68 | U18: 25579 | V18: 11 | W18: 4 | X18: 24 | Y18: 0.28205128 | Z18: 0.1025641 | AA18: 0.61538462
A19: 16-18% | B19: 185 | C19: 29 | U19: 25586 | V19: 5 | W19: 1 | X19: 19 | Y19: 0.2 | Z19: 0.04 | AA19: 0.76
A20: 18-20% | B20: 138 | C20: 23 | U20: 25593 | V20: 8 | W20: 0 | X20: 12 | Y20: 0.4 | Z20: 0 | AA20: 0.6
A21: 18-22% | B21: 119 | C21: 12 | U21: 25600 | V21: 9 | W21: 4 | X21: 5 | Y21: 0.5 | Z21: 0.22222222 | AA21: 0.27777778
... A23: 18-20% | B23: 176 | C23: 6 | U23: 25614 | V23: 22 | W23: 2 | X23: 4 | Y23: 0.78571429 | Z23: 0.071428571 | AA23: 0.14285714
U24: 25621 | V24: 15 | W24: 5 | X24: 9 | Y24: 0.51724138 | Z24: 0.17241379 | AA24: 0.31034483
B25: =Sommaire!C50 -> Figure 25 : Chaque nom divin a son profil grammatical. | U25: 25628 | V25: 17 | W25: 16 | X25: 27 | Y25: 0.28333333 | Z25: 0.26666667 | AA25: 0.45
A26: Répartition des fonctions attribuées à chaque nom divin | U26: 25635 | V26: 8 | W26: 1 | X26: 14 | Y26: 0.34782609 | Z26: 0.043478261 | AA26: 0.60869565
A27: Prise en compte des 7 noms divins, sans les pronoms personnels qui les désignent. | U27: 25642 | V27: 9 | W27: 4 | X27: 6 | Y27: 0.47368421 | Z27: 0.21052632 | AA27: 0.31578947
A28: outil : spaCy | U28: 25649 | V28: 7 | W28: 5 | X28: 22 | Y28: 0.20588235 | Z28: 0.14705882 | AA28: 0.64705882
B29: Dieu | C29: Jésus | D29: Christ | E29: Seigneur | F29: Esprit | G29: Père | H29: Fils | I29: TOTAL | U29: 25663 | V29: 15 | W29: 7 | X29: 11 | Y29: 0.45454545 | Z29: 0.21212121 | AA29: 0.33333333
A30: Sujet | B30: 0.29601329 | C30: 0.4273342 | D30: 0.30469405 | E30: 0.33175751 | F30: 0.41269319 | G30: 0.24948875 | H30: 0.37248935 | I30: 0.3401785 | U30: 25670 | V30: 6 | W30: 13 | X30: 8 | Y30: 0.22222222 | Z30: 0.48148148 | AA30: 0.2962963
A31: Objet | B31: 0.21196013 | C31: 0.24196227 | D31: 0.20819363 | E31: 0.26557286 | F31: 0.25682341 | G31: 0.34764826 | H31: 0.3432745 | I31: 0.23574817 | U31: 25677 | V31: 3 | W31: 1 | X31: 8 | Y31: 0.25 | Z31: 0.083333333 | AA31: 0.66666667
A32: Complément du Nom | B32: 0.49202658 | C32: 0.33070352 | D32: 0.48711232 | E32: 0.40266963 | F32: 0.33048339 | G32: 0.40286299 | H32: 0.28423615 | I32: 0.42407333 | U32: 25684 | V32: 1 | W32: 6 | X32: 2 | Y32: 0.11111111 | Z32: 0.66666667 | AA32: 0.22222222
U33: 25691 | V33: 16 | W33: 12 | X33: 17 | Y33: 0.35555556 | Z33: 0.26666667 | AA33: 0.37777778
U34: 25698 | V34: 8 | W34: 6 | X34: 8 | Y34: 0.36363636 | Z34: 0.27272727 | AA34: 0.36363636
U35: 25705 | V35: 7 | W35: 3 | X35: 14 | Y35: 0.29166667 | Z35: 0.125 | AA35: 0.58333333
U36: 25712 | V36: 4 | W36: 3 | X36: 12 | Y36: 0.21052632 | Z36: 0.15789474 | AA36: 0.63157895
U37: 25719 | V37: 4 | W37: 3 | X37: 5 | Y37: 0.33333333 | Z37: 0.25 | AA37: 0.41666667
U38: 25726 | V38: 14 | W38: 6 | X38: 9 | Y38: 0.48275862 | Z38: 0.20689655 | AA38: 0.31034483
B39: =Sommaire!C51 -> Figure 26 : Dieu est-il fréquemment nommé, et sujet chez les prédicateurs ? | U39: 25733 | V39: 2 | W39: 5 | X39: 6 | Y39: 0.15384615 | Z39: 0.38461538 | AA39: 0.46153846
A40: Répartition des principaux prédicateurs selon la fréquence avec laquelle ils nomment Dieu, la fréquence avec laquelle ils le nomment comme sujet, | U40: 25740 | V40: 14 | W40: 7 | X40: 15 | Y40: 0.38888889 | Z40: 0.19444444 | AA40: 0.41666667
A41: Prise en compte des 7 noms divins, sans les pronoms personnels qui les désignent. | U41: 25754 | V41: 4 | W41: 6 | X41: 10 | Y41: 0.2 | Z41: 0.3 | AA41: 0.5
A42: outil : spaCy | U42: 25761 | V42: 6 | W42: 1 | X42: 3 | Y42: 0.6 | Z42: 0.1 | AA42: 0.3
...

Sheet Verbes
B1: =Sommaire!B55 -> Onglet "Verbes"
B4: Figures 31-32 : Chaque corpus a un usage différent des types de verbes
A5: Les pronoms personnels qui les désignent sont pris en compte
A6: outil : spaCy
B8: Corpus | C8: Évangiles | D8: Épitres | E8: Psaumes | F8: Catéchisme | G8: Coaching | H8: Roman
A9: Physiologie | B9: 0.044966378 | C9: 0.037200918 | D9: 0.040790756 | E9: 0.044138253 | F9: 0.035492458 | G9: 0.028729612 | H9: 0.028138528
A10: Perception | B10: 0.051708052 | C10: 0.055145854 | D10: 0.031045524 | E10: 0.056515647 | F10: 0.015084295 | G10: 0.04713452 | H10: 0.017316017
A11: Émotion | B11: 0.019063975 | C11: 0.011471649 | D11: 0.02199638 | E11: 0.035964503 | F11: 0.043478261 | G11: 0.029402963 | H11: 0.053030303
A12: Cognition | B12: 0.10128061 | C12: 0.060553917 | D12: 0.081442294 | E12: 0.067258291 | F12: 0.060337178 | G12: 0.12666467 | H12: 0.062770563
A13: Volonté | B13: 0.093084169 | C13: 0.043920026 | D13: 0.068077405 | E13: 0.050210182 | F13: 0.04880213 | G13: 0.079679785 | H13: 0.048701299
A15: Communication | B15: 0.19665577 | C15: 0.24057686 | D15: 0.17611026 | E15: 0.14175619 | F15: 0.20763088 | G15: 0.15599282 | H15: 0.16558442
A16: Transaction | B16: 0.13803673 | C16: 0.1502786 | D16: 0.19532229 | E16: 0.13872022 | F16: 0.13664596 | G16: 0.16766422 | H16: 0.13311688
A17: Mouvement | B17: 0.1615652 | C17: 0.24606686 | D17: 0.14506474 | E17: 0.19243344 | F17: 0.1162378 | G17: 0.14955858 | H17: 0.17424242
A18: Transformation | B18: 0.11916626 | C18: 0.090789905 | D18: 0.14353334 | E18: 0.13568426 | F18: 0.18278616 | G18: 0.15741433 | H18: 0.16233766
A19: Altération | B19: 0.037188055 | C19: 0.030809571 | D19: 0.046637895 | E19: 0.07823447 | F19: 0.09228039 | G19: 0.024913961 | H19: 0.10822511
A20: Soin | B20: 0.037592348 | C20: 0.033185841 | D20: 0.049979117 | E20: 0.05908454 | F20: 0.06122449 | G20: 0.032844531 | H20: 0.046536797
B28: Les verbes présents dans la Bible
A29: Répartition des verbes selon les livres bibliques, par catégories étudiées
A30: outil : spaCy | B30: traduction : Aelf
B32: Physiologie | C32: Sens | D32: Emotion | E32: Cognitif | F32: Volonté | G32: Communication | H32: Transaction | I32: Mouvement | J32: Transformation | K32: Confrontation
A33: Gn | B33: 0.08731393 | C33: 0.040879804 | D33: 0.0099977783 | E33: 0.045101089 | F33: 0.024661186 | G33: 0.2070651 | H33: 0.14796712 | I33: 0.24883359 | J33: 0.12019551 | K33: 0.032659409
A34: Ex | B34: 0.044231919 | C34: 0.037358039 | D34: 0.0068738793 | E34: 0.033771668 | F34: 0.022115959 | G34: 0.17513449 | H34: 0.14763897 | I34: 0.25313808 | J34: 0.19396294 | K34: 0.049013748
A35: Lv | B35: 0.063066777 | C35: 0.019785655 | D35: 0.005358615 | E35: 0.056059357 | F35: 0.016075845 | G35: 0.11995054 | H35: 0.1793075 | I35: 0.20362737 | J35: 0.23577906 | K35: 0.045342127
A36: Nb | B36: 0.04976775 | C36: 0.026874585 | D36: 0.0066357001 | E36: 0.03583278 | F36: 0.02256138 | G36: 0.18978102 | H36: 0.18779031 | I36: 0.26907764 | J36: 0.13636364 | K36: 0.04777704
A37: Dt | B37: 0.062584118 | C37: 0.046433378 | D37: 0.019851952 | E37: 0.048452221 | F37: 0.045087483 | G37: 0.13829071 | H37: 0.1628533 | I37: 0.23990579 | J37: 0.12987887 | K37: 0.060228802
A38: Jos | B38: 0.035672515 | C38: 0.020467836 | D38: 0.0064327485 | E38: 0.035087719 | F38: 0.018128655 | G38: 0.15964912 | H38: 0.16549708 | I38: 0.32397661 | J38: 0.12807018 | K38: 0.074853801
A39: Jg | B39: 0.04563405 | C39: 0.025449759 | D39: 0.011408513 | E39: 0.04168495 | F39: 0.02896007 | G39: 0.17814831 | H39: 0.14436156 | I39: 0.29925406 | J39: 0.11671786 | K39: 0.075471698
A40: Rt | B40: 0.085790885 | C40: 0.013404826 | D40: 0.010723861 | E40: 0.061662198 | F40: 0.029490617 | G40: 0.22252011 | H40: 0.14745308 | I40: 0.26541555 | J40: 0.091152815 | K40: 0.021447721
A41: 1S | B41: 0.028763183 | C41: 0.037072547 | D41: 0.014062001 | E41: 0.054969639 | F41: 0.026526047 | G41: 0.20549696 | H41: 0.14285714 | I41: 0.29849792 | J41: 0.10866091 | K41: 0.054650048
A42: 2S | B42: 0.03986711 | C42: 0.02076412 | D42: 0.010797342 | E42: 0.044850498 | F42: 0.021594684 | G42: 0.20930233 | H42: 0.12873754 | I42: 0.32018272 | J42: 0.11586379 | K42: 0.057724252
A43: 1R | B43: 0.050699962 | C43: 0.026863413 | D43: 0.0071888006 | E43: 0.038592509 | F43: 0.022323118 | G43: 0.19977299 | H43: 0.14528944 | I43: 0.27090428 | J43: 0.15626182 | K43: 0.043889519
A44: 2R | B44: 0.034831461 | C44: 0.031835206 | D44: 0.01011236 | E44: 0.034831461 | F44: 0.016853933 | G44: 0.19250936 | H44: 0.1258427 | I44: 0.31423221 | J44: 0.13071161 | K44: 0.074906367
... A100: Ap | B100: 0.03030303 | C100: 0.098280098 | D100: 0.012285012 | E100: 0.040950041 | F100: 0.022932023 | G100: 0.18018018 | H100: 0.15151515 | I100: 0.25716626 | J100: 0.11957412 | K100: 0.05978706
A101: Bible | B101: 0.045556283 | C101: 0.039538419 | D101: 0.016079309 | E101: 0.054804789 | F101: 0.03548428 | G101: 0.1836293 | H101: 0.14461876 | I101: 0.2436918 | J101: 0.13694335 | K101: 0.058890602 | L101: 0.040763107
B103: Figures 33-34 : De quels verbes les noms divins sont-ils le sujet ?
A104: Les pronoms personnels qui les désignent sont pris en compte
A105: outil : spaCy
B106: Corpus | C106: 5 Noms divins | D106: Dieu | E106: Jésus | F106: Christ | G106: Seigneur | H106: Esprit
A107: Physiologie | B107: 0.042761844 | C107: 0.034470588 | D107: 0.032840958 | E107: 0.031144332 | F107: 0.051040312 | G107: 0.02744097 | H107: 0.052826691
A108: Sensibilité | B108: 0.073271883 | C108: 0.044470588 | D108: 0.041302165 | E108: 0.047428368 | F108: 0.041287386 | G108: 0.050095724 | H108: 0.026876738
...
